2024-07-18T14:00:35.294540+00:00 app[web.1]: ^^^^^^^^^^^^^^^^^^^^^^^^^^
2024-07-18T14:00:35.294540+00:00 app[web.1]: File "/app/.heroku/python/lib/python3.12/site-packages/django/core/handlers/exception.py", line 57, in inner
2024-07-18T14:00:35.294540+00:00 app[web.1]: response = response_for_exception(request, exc)
2024-07-18T14:00:35.294540+00:00 app[web.1]: ^^^^^^^^^^^^^^^^^^^^^^^^^^^^^^^^^^^^
2024-07-18T14:00:35.294540+00:00 app[web.1]: File "/app/.heroku/python/lib/python3.12/site-packages/django/core/handlers/exception.py", line 140, in response_for_exception
2024-07-18T14:00:35.294540+00:00 app[web.1]: response = handle_uncaught_exception(
2024-07-18T14:00:35.294540+00:00 app[web.1]: ^^^^^^^^^^^^^^^^^^^^^^^^^^
2024-07-18T14:00:35.294541+00:00 app[web.1]: File "/app/.heroku/python/lib/python3.12/site-packages/django/core/handlers/exception.py", line 181, in handle_uncaught_exception
2024-07-18T14:00:35.294541+00:00 app[web.1]: return debug.technical_500_response(request, *exc_info)
2024-07-18T14:00:35.294541+00:00 app[web.1]: ^^^^^^^^^^^^^^^^^^^^^^^^^^^^^^^^^^^^^^^^^^^^^^^^
2024-07-18T14:00:35.294541+00:00 app[web.1]: File "/app/.heroku/python/lib/python3.12/site-packages/django/views/debug.py", line 67, in technical_500_response
2024-07-18T14:00:35.294541+00:00 app[web.1]: html = reporter.get_traceback_html()
2024-07-18T14:00:35.294541+00:00 app[web.1]: ^^^^^^^^^^^^^^^^^^^^^^^^^^^^^
2024-07-18T14:00:35.294541+00:00 app[web.1]: File "/app/.heroku/python/lib/python3.12/site-packages/django/views/debug.py", line 410, in get_traceback_html
2024-07-18T14:00:35.294541+00:00 app[web.1]: c = Context(self.get_traceback_data(), use_l10n=False)
2024-07-18T14:00:35.294542+00:00 app[web.1]: ^^^^^^^^^^^^^^^^^^^^^^^^^
2024-07-18T14:00:35.294542+00:00 app[web.1]: File "/app/.heroku/python/lib/python3.12/site-packages/django/views/debug.py", line 379, in get_traceback_data
2024-07-18T14:00:35.294542+00:00 app[web.1]: "settings": self.filter.get_safe_settings(),
2024-07-18T14:00:35.294542+00:00 app[web.1]: ^^^^^^^^^^^^^^^^^^^^^^^^^^^^^^^
2024-07-18T14:00:35.294542+00:00 app[web.1]: File "/app/.heroku/python/lib/python3.12/site-packages/django/views/debug.py", line 154, in get_safe_settings
2024-07-18T14:00:35.294542+00:00 app[web.1]: settings_dict[k] = self.cleanse_setting(k, getattr(settings, k))
2024-07-18T14:00:35.294542+00:00 app[web.1]: ^^^^^^^^^^^^^^^^^^^^
2024-07-18T14:00:35.294542+00:00 app[web.1]: File "/app/.heroku/python/lib/python3.12/site-packages/django/conf/__init__.py", line 111, in __getattr__
2024-07-18T14:00:35.294542+00:00 app[web.1]: raise ImproperlyConfigured("The SECRET_KEY setting must not be empty.")
2024-07-18T14:00:35.294543+00:00 app[web.1]: django.core.exceptions.ImproperlyConfigured: The SECRET_KEY setting must not be empty.
2024-07-18T14:00:35.294543+00:00 app[web.1]: 
2024-07-18T14:00:35.294543+00:00 app[web.1]: During handling of the above exception, another exception occurred:
2024-07-18T14:00:35.294543+00:00 app[web.1]: 
2024-07-18T14:00:35.294543+00:00 app[web.1]: Traceback (most recent call last):
2024-07-18T14:00:35.294543+00:00 app[web.1]: File "/app/.heroku/python/lib/python3.12/site-packages/django/core/handlers/exception.py", line 55, in inner
2024-07-18T14:00:35.294543+00:00 app[web.1]: response = get_response(request)
2024-07-18T14:00:35.294543+00:00 app[web.1]: ^^^^^^^^^^^^^^^^^^^^^
2024-07-18T14:00:35.294543+00:00 app[web.1]: File "/app/.heroku/python/lib/python3.12/site-packages/django/utils/deprecation.py", line 134, in __call__
2024-07-18T14:00:35.294544+00:00 app[web.1]: response = response or self.get_response(request)
2024-07-18T14:00:35.294544+00:00 app[web.1]: ^^^^^^^^^^^^^^^^^^^^^^^^^^
2024-07-18T14:00:35.294544+00:00 app[web.1]: File "/app/.heroku/python/lib/python3.12/site-packages/django/core/handlers/exception.py", line 57, in inner
2024-07-18T14:00:35.294545+00:00 app[web.1]: response = response_for_exception(request, exc)
2024-07-18T14:00:35.294545+00:00 app[web.1]: ^^^^^^^^^^^^^^^^^^^^^^^^^^^^^^^^^^^^
2024-07-18T14:00:35.294547+00:00 app[web.1]: File "/app/.heroku/python/lib/python3.12/site-packages/django/core/handlers/exception.py", line 140, in response_for_exception
2024-07-18T14:00:35.294547+00:00 app[web.1]: response = handle_uncaught_exception(
2024-07-18T14:00:35.294547+00:00 app[web.1]: ^^^^^^^^^^^^^^^^^^^^^^^^^^
2024-07-18T14:00:35.294547+00:00 app[web.1]: File "/app/.heroku/python/lib/python3.12/site-packages/django/core/handlers/exception.py", line 181, in handle_uncaught_exception
2024-07-18T14:00:35.294547+00:00 app[web.1]: return debug.technical_500_response(request, *exc_info)
2024-07-18T14:00:35.294547+00:00 app[web.1]: ^^^^^^^^^^^^^^^^^^^^^^^^^^^^^^^^^^^^^^^^^^^^^^^^
2024-07-18T14:00:35.294548+00:00 app[web.1]: File "/app/.heroku/python/lib/python3.12/site-packages/django/views/debug.py", line 67, in technical_500_response
2024-07-18T14:00:35.294548+00:00 app[web.1]: html = reporter.get_traceback_html()
2024-07-18T14:00:35.294548+00:00 app[web.1]: ^^^^^^^^^^^^^^^^^^^^^^^^^^^^^
2024-07-18T14:00:35.294548+00:00 app[web.1]: File "/app/.heroku/python/lib/python3.12/site-packages/django/views/debug.py", line 410, in get_traceback_html
2024-07-18T14:00:35.294548+00:00 app[web.1]: c = Context(self.get_traceback_data(), use_l10n=False)
2024-07-18T14:00:35.294548+00:00 app[web.1]: ^^^^^^^^^^^^^^^^^^^^^^^^^
2024-07-18T14:00:35.294548+00:00 app[web.1]: File "/app/.heroku/python/lib/python3.12/site-packages/django/views/debug.py", line 379, in get_traceback_data
2024-07-18T14:00:35.294549+00:00 app[web.1]: "settings": self.filter.get_safe_settings(),
2024-07-18T14:00:35.294549+00:00 app[web.1]: ^^^^^^^^^^^^^^^^^^^^^^^^^^^^^^^
2024-07-18T14:00:35.294549+00:00 app[web.1]: File "/app/.heroku/python/lib/python3.12/site-packages/django/views/debug.py", line 154, in get_safe_settings
2024-07-18T14:00:35.294549+00:00 app[web.1]: settings_dict[k] = self.cleanse_setting(k, getattr(settings, k))
2024-07-18T14:00:35.294549+00:00 app[web.1]: ^^^^^^^^^^^^^^^^^^^^
2024-07-18T14:00:35.294549+00:00 app[web.1]: File "/app/.heroku/python/lib/python3.12/site-packages/django/conf/__init__.py", line 111, in __getattr__
2024-07-18T14:00:35.294549+00:00 app[web.1]: raise ImproperlyConfigured("The SECRET_KEY setting must not be empty.")
2024-07-18T14:00:35.294550+00:00 app[web.1]: django.core.exceptions.ImproperlyConfigured: The SECRET_KEY setting must not be empty.
2024-07-18T14:00:35.294550+00:00 app[web.1]: 
2024-07-18T14:00:35.294550+00:00 app[web.1]: During handling of the above exception, another exception occurred:
2024-07-18T14:00:35.294550+00:00 app[web.1]: 
2024-07-18T14:00:35.294550+00:00 app[web.1]: Traceback (most recent call last):
2024-07-18T14:00:35.294550+00:00 app[web.1]: File "/app/.heroku/python/lib/python3.12/site-packages/gunicorn/workers/sync.py", line 136, in handle
2024-07-18T14:00:35.294550+00:00 app[web.1]: self.handle_request(listener, req, client, addr)
2024-07-18T14:00:35.294550+00:00 app[web.1]: File "/app/.heroku/python/lib/python3.12/site-packages/gunicorn/workers/sync.py", line 179, in handle_request
2024-07-18T14:00:35.294551+00:00 app[web.1]: respiter = self.wsgi(environ, resp.start_response)
2024-07-18T14:00:35.294551+00:00 app[web.1]: ^^^^^^^^^^^^^^^^^^^^^^^^^^^^^^^^^^^^^^^
2024-07-18T14:00:35.294551+00:00 app[web.1]: File "/app/.heroku/python/lib/python3.12/site-packages/django/core/handlers/wsgi.py", line 124, in __call__
2024-07-18T14:00:35.294551+00:00 app[web.1]: response = self.get_response(request)
2024-07-18T14:00:35.294551+00:00 app[web.1]: ^^^^^^^^^^^^^^^^^^^^^^^^^^
2024-07-18T14:00:35.294551+00:00 app[web.1]: File "/app/.heroku/python/lib/python3.12/site-packages/django/core/handlers/base.py", line 140, in get_response
2024-07-18T14:00:35.294551+00:00 app[web.1]: response = self._middleware_chain(request)
2024-07-18T14:00:35.294551+00:00 app[web.1]: ^^^^^^^^^^^^^^^^^^^^^^^^^^^^^^^
2024-07-18T14:00:35.294552+00:00 app[web.1]: File "/app/.heroku/python/lib/python3.12/site-packages/django/core/handlers/exception.py", line 57, in inner
2024-07-18T14:00:35.294552+00:00 app[web.1]: response = response_for_exception(request, exc)
2024-07-18T14:00:35.294552+00:00 app[web.1]: ^^^^^^^^^^^^^^^^^^^^^^^^^^^^^^^^^^^^
2024-07-18T14:00:35.294552+00:00 app[web.1]: File "/app/.heroku/python/lib/python3.12/site-packages/django/core/handlers/exception.py", line 140, in response_for_exception
2024-07-18T14:00:35.294552+00:00 app[web.1]: response = handle_uncaught_exception(
2024-07-18T14:00:35.294552+00:00 app[web.1]: ^^^^^^^^^^^^^^^^^^^^^^^^^^
2024-07-18T14:00:35.294552+00:00 app[web.1]: File "/app/.heroku/python/lib/python3.12/site-packages/django/core/handlers/exception.py", line 181, in handle_uncaught_exception
2024-07-18T14:00:35.294552+00:00 app[web.1]: return debug.technical_500_response(request, *exc_info)
2024-07-18T14:00:35.294552+00:00 app[web.1]: ^^^^^^^^^^^^^^^^^^^^^^^^^^^^^^^^^^^^^^^^^^^^^^^^
2024-07-18T14:00:35.294553+00:00 app[web.1]: File "/app/.heroku/python/lib/python3.12/site-packages/django/views/debug.py", line 67, in technical_500_response
2024-07-18T14:00:35.294553+00:00 app[web.1]: html = reporter.get_traceback_html()
2024-07-18T14:00:35.294553+00:00 app[web.1]: ^^^^^^^^^^^^^^^^^^^^^^^^^^^^^
2024-07-18T14:00:35.294553+00:00 app[web.1]: File "/app/.heroku/python/lib/python3.12/site-packages/django/views/debug.py", line 410, in get_traceback_html
2024-07-18T14:00:35.294553+00:00 app[web.1]: c = Context(self.get_traceback_data(), use_l10n=False)
2024-07-18T14:00:35.294553+00:00 app[web.1]: ^^^^^^^^^^^^^^^^^^^^^^^^^
2024-07-18T14:00:35.294553+00:00 app[web.1]: File "/app/.heroku/python/lib/python3.12/site-packages/django/views/debug.py", line 379, in get_traceback_data
2024-07-18T14:00:35.294553+00:00 app[web.1]: "settings": self.filter.get_safe_settings(),
2024-07-18T14:00:35.294554+00:00 app[web.1]: ^^^^^^^^^^^^^^^^^^^^^^^^^^^^^^^
2024-07-18T14:00:35.294554+00:00 app[web.1]: File "/app/.heroku/python/lib/python3.12/site-packages/django/views/debug.py", line 154, in get_safe_settings
2024-07-18T14:00:35.294554+00:00 app[web.1]: settings_dict[k] = self.cleanse_setting(k, getattr(settings, k))
2024-07-18T14:00:35.294554+00:00 app[web.1]: ^^^^^^^^^^^^^^^^^^^^
2024-07-18T14:00:35.294555+00:00 app[web.1]: File "/app/.heroku/python/lib/python3.12/site-packages/django/conf/__init__.py", line 111, in __getattr__
2024-07-18T14:00:35.294555+00:00 app[web.1]: raise ImproperlyConfigured("The SECRET_KEY setting must not be empty.")
2024-07-18T14:00:35.294555+00:00 app[web.1]: django.core.exceptions.ImproperlyConfigured: The SECRET_KEY setting must not be empty.
2024-07-18T14:00:35.294740+00:00 app[web.1]: 10.1.11.91 - - [18/Jul/2024:14:00:35 +0000] "GET /favicon.ico HTTP/1.1" 500 0 "-" "-"
2024-07-18T14:00:35.295291+00:00 heroku[router]: at=info method=GET path="/favicon.ico" host=restaurant-booking-systems-c7e901b3d3c6.herokuapp.com request_id=76a4ec85-ee04-4a92-8aab-3b22534f510b fwd="78.69.199.72" dyno=web.1 connect=0ms service=246ms status=500 bytes=244 protocol=https